<?xml version="1.0" encoding="utf-8"?>
<!-- =================================================================================== -->
<!-- |    This document was autogenerated by xacro from /home/vamaro/catkin_ws/src/my_robot_description/urdf/my_robot.xacro | -->
<!-- |    EDITING THIS FILE BY HAND IS NOT RECOMMENDED                                 | -->
<!-- =================================================================================== -->
<robot name="robot" xmlns:controller="http://playerstage.sourceforge.net/gazebo/xmlschema/#controller" xmlns:interface="http://playerstage.sourceforge.net/gazebo/xmlschema/#interface" xmlns:sensor="http://playerstage.sourceforge.net/gazebo/xmlschema/#sensor">
  <!-- friction = friccao, damping =  reducao de oscilacoes, ou vibracoes -->
  <!-- 
<link name="dummy">
</link> -->
  <link name="base_link">
    <pose>0 0 1 0 0 0 </pose>
    <!-- x y z ro rotacao -->
    <inertial>
      <mass value="50"/>
      <origin rpy="0 0 0" xyz="0 0 0"/>
      <inertia ixx="0.3954166667" ixy="0" ixz="0" iyy="0.10620833" iyz="0" izz="0.1062083333"/>
    </inertial>
    <collision name="collision_chassis">
      <geometry>
        <box size="0.8 0.8 0.6"/>
      </geometry>
    </collision>
    <visual>
      <origin rpy="0 0 0" xyz="0 0 0"/>
      <geometry>
        <box size="0.8 0.8 0.4"/>
      </geometry>
      <material name="Cyan">
        <color rgba="0 1.0 1.0 1.0"/>
      </material>
    </visual>
  </link>
  <static>true</static>
  <link name="base">
    <pose>0 0 0 0 0 </pose>
    <inertial>
      <mass value="2"/>
      <origin rpy="0 0 0" xyz="0 0 0.5"/>
      <inertia ixx="0.3954166667" ixy="0" ixz="0" iyy="0.10620833" iyz="0" izz="0.1062083333"/>
    </inertial>
    <collision name="collision_chassis">
      <geometry>
        <cylinder length="0.5" radius="0.25"/>
      </geometry>
    </collision>
    <visual>
      <origin rpy="0 0 0" xyz="0 0 0"/>
      <geometry>
        <cylinder length="0.5" radius="0.25"/>
      </geometry>
      <material name="Yellow">
        <color rgba="0 1.0 0.2 1.0"/>
      </material>
    </visual>
    <!-- quadrados suporte -->
    <visual>
      <origin rpy="0 0 0" xyz="0 0.2 0.45"/>
      <geometry>
        <box size="0.4 0.07 0.4"/>
        <!-- x y z   -->
      </geometry>
      <material name="Blue">
        <color rgba="0 0 0.8 1"/>
      </material>
    </visual>
    <visual>
      <origin rpy="0 0 0" xyz="0 -0.2 0.45"/>
      <geometry>
        <box size="0.4 0.07 0.4"/>
      </geometry>
      <material name="Blue">
        <color rgba="0 0 0.8 1"/>
      </material>
    </visual>
  </link>
  <static>true</static>
  <link name="ligacao">
    <pose>0 0 0 0 0 </pose>
    <inertial>
      <mass value="0.5"/>
      <origin rpy="0 0 0" xyz="0 0 0"/>
      <inertia ixx="0.3954166667" ixy="0" ixz="0" iyy="0.10620833" iyz="0" izz="0.1062083333"/>
    </inertial>
    <collision name="collision_chassis">
      <origin rpy="0 0 0" xyz="0 0 0.5"/>
      <geometry>
        <cylinder length="1" radius="0.15"/>
      </geometry>
    </collision>
    <visual>
      <origin rpy="0 0 0" xyz="0 0 0.5"/>
      <geometry>
        <cylinder length="1" radius="0.15"/>
      </geometry>
      <material name="Green">
        <color rgba="0 1.0 0.2 1.0"/>
      </material>
    </visual>
    <visual>
      <origin rpy="0 0 0" xyz="0 0.17 1.13"/>
      <geometry>
        <box size="0.4 0.05 0.5"/>
      </geometry>
      <material name="Blue">
        <color rgba="0 0 0.8 1"/>
      </material>
    </visual>
    <visual>
      <origin rpy="0 0 0" xyz="0 -0.17 1.13"/>
      <geometry>
        <box size="0.4 0.05 0.5"/>
      </geometry>
      <material name="Blue">
        <color rgba="0 0 0.8 1"/>
      </material>
    </visual>
    <collision name="collision_chassis">
      <origin rpy="1.58 0 0" xyz="0 0 -0.07"/>
      <geometry>
        <cylinder length="0.3" radius="0.2"/>
      </geometry>
    </collision>
    <visual>
      <origin rpy="1.58 0 0" xyz="0 0 -0.07"/>
      <geometry>
        <cylinder length="0.3" radius="0.2"/>
      </geometry>
      <material name="Yellow">
        <color rgba="1.0 1.0 0 1.0"/>
      </material>
    </visual>
  </link>
  <static>true</static>
  <link name="braco">
    <pose>0 0 0 0 0 </pose>
    <inertial>
      <mass value="0.5"/>
      <origin rpy="0 0 0" xyz="0 0 2"/>
      <inertia ixx="0.3954166667" ixy="0" ixz="0" iyy="0.10620833" iyz="0" izz="0.1062083333"/>
    </inertial>
    <collision name="collision_chassis">
      <origin rpy="0 0 0" xyz="0 0 0.7"/>
      <geometry>
        <cylinder length="1" radius="0.125"/>
      </geometry>
    </collision>
    <visual>
      <origin rpy="0 0 0" xyz="0 0 0.7"/>
      <geometry>
        <cylinder length="1" radius="0.125"/>
      </geometry>
      <material name="Red">
        <color rgba="0 2.0 1.0 1.0"/>
      </material>
    </visual>
    <collision name="suporte_cilindro">
      <origin rpy="1.58 0 0" xyz="0 0 0.04"/>
      <geometry>
        <cylinder length="0.3" radius="0.2"/>
      </geometry>
    </collision>
    <visual>
      <origin rpy="1.58 0 0" xyz="0 0 0.04"/>
      <geometry>
        <cylinder length="0.3" radius="0.2"/>
      </geometry>
      <material name="yellow">
        <color rgba="1.0 1.0 0 1.0"/>
      </material>
    </visual>
  </link>
  <static>true</static>
  <link name="antepunho">
    <pose>0 0 0 0 0 </pose>
    <inertial>
      <mass value="0.1"/>
      <origin rpy="0 0 0" xyz="0 0 2"/>
      <inertia ixx="0.3954166667" ixy="0" ixz="0" iyy="0.10620833" iyz="0" izz="0.1062083333"/>
    </inertial>
    <collision name="collision_chassis">
      <geometry>
        <sphere length="1.2" radius="0.12"/>
      </geometry>
    </collision>
    <visual>
      <origin rpy="0 0 0" xyz="0 0 0"/>
      <geometry>
        <sphere length="1.2" radius="0.12"/>
      </geometry>
      <material name="Blue">
        <color rgba="0 0 0.8 1"/>
      </material>
    </visual>
    <visual>
      <origin rpy="0 0 0" xyz="0 0 0.16"/>
      <geometry>
        <box size="0.05 0.14 0.12"/>
      </geometry>
      <material name="Yellow">
        <color rgba="1.0 1.0 0 1.0"/>
      </material>
    </visual>
  </link>
  <link name="punho">
    <pose>0 0 0 0 0 </pose>
    <inertial>
      <mass value="0.1"/>
      <origin rpy="0 0 0" xyz="0 0 2"/>
      <inertia ixx="0.3954166667" ixy="0" ixz="0" iyy="0.10620833" iyz="0" izz="0.1062083333"/>
    </inertial>
    <collision name="collision_chassis">
      <origin rpy="0 0 0" xyz="0 0 0.1"/>
      <geometry>
        <cylinder length="0.01" radius="0.1"/>
      </geometry>
    </collision>
    <visual>
      <origin rpy="0 0 0" xyz="0 0 0.1"/>
      <geometry>
        <cylinder length="0.01" radius="0.1"/>
      </geometry>
      <material name="Blue">
        <color rgba="0 0 0.8 1"/>
      </material>
    </visual>
  </link>
  <link name="riser">
    <pose>0 0 0 0 0 </pose>
    <inertial>
      <mass value="0.2"/>
      <origin rpy="0.02 0 0" xyz="0 0 0"/>
      <inertia ixx="0.01" ixy="0" ixz="0" iyy="0.01" iyz="0" izz="0.01"/>
    </inertial>
    <collision name="collision_chassis">
      <origin rpy="0 -1.55 0" xyz="0 0 0.2"/>
      <geometry>
        <box size="0.2 0.2 1.0"/>
      </geometry>
    </collision>
    <visual>
      <origin rpy="0 -1.55 0" xyz="0 0 0.2"/>
      <geometry>
        <box size="0.2 0.2 1.0"/>
      </geometry>
      <material name="Blue">
        <color rgba="0 0 0.8 1"/>
      </material>
    </visual>
  </link>
  <link name="palm">
    <pose>0 0 0 0 0 </pose>
    <inertial>
      <mass value="0.2"/>
      <origin rpy="0 0 0" xyz="-0.6 0 0.35"/>
      <inertia ixx="0.01" ixy="0" ixz="0" iyy="0.01" iyz="0" izz="0.01"/>
    </inertial>
    <collision name="collision_chassis">
      <origin rpy="0 0 0" xyz="-0.6 0 0.35"/>
      <geometry>
        <box size="0.1 0.2 0.1"/>
      </geometry>
    </collision>
    <visual>
      <origin rpy="0 0 0" xyz="-0.6 0 0.35"/>
      <geometry>
        <box size="0.1 0.2 0.1"/>
      </geometry>
      <material name="Blue">
        <color rgba="0 0 0.8 1"/>
      </material>
    </visual>
  </link>
  <link name="left_finger">
    <pose>0 0 0 0 0 </pose>
    <inertial>
      <mass value="0.1"/>
      <origin rpy="0 0 0" xyz="0 0 0"/>
      <inertia ixx="0.01" ixy="0" ixz="0" iyy="0.01" iyz="0" izz="0.01"/>
    </inertial>
    <collision name="collision_chassis">
      <origin rpy="0.67 0 0" xyz="-0.6 0.14 0.4"/>
      <geometry>
        <box size="0.1 0.3 0.1"/>
      </geometry>
    </collision>
    <visual>
      <origin rpy="0.67 0 0" xyz="-0.6 0.14 0.4"/>
      <geometry>
        <box size="0.1 0.3 0.1"/>
      </geometry>
      <material name="Blue">
        <color rgba="0 0 0.8 1"/>
      </material>
    </visual>
  </link>
  <link name="right_finger">
    <pose>0.1 -0.2 0.05 0 0 </pose>
    <inertial>
      <mass value="0.1"/>
      <origin rpy="0 0 0" xyz="0 0 0"/>
      <inertia ixx="0.01" ixy="0" ixz="0" iyy="0.01" iyz="0" izz="0.01"/>
    </inertial>
    <collision name="collision_chassis">
      <origin rpy="-0.67 0 0" xyz="-0.6 -0.14 0.4"/>
      <geometry>
        <box size="0.1 0.3 0.1"/>
      </geometry>
    </collision>
    <visual>
      <origin rpy="-0.67 0 0" xyz="-0.6 -0.14 0.4"/>
      <geometry>
        <box size="0.1 0.3 0.1"/>
      </geometry>
      <material name="Blue">
        <color rgba="0 0 0.8 1"/>
      </material>
    </visual>
  </link>
  <link name="l_finger_tip">
    <pose>0 0 0 0 0 </pose>
    <inertial>
      <origin rpy="0 0 0" xyz="0 0 0"/>
      <mass value="0.1"/>
      <inertia ixx="0.01" ixy="0" ixz="0" iyy="0.01" iyz="0" izz="0.01"/>
    </inertial>
    <collision name="collision_chassis">
      <origin rpy="1.5 0 0" xyz="-0.6 0.25 0.57"/>
      <geometry>
        <box size="0.1 0.2 0.1"/>
      </geometry>
    </collision>
    <visual>
      <origin rpy="1.5 0 0" xyz="-0.6 0.25 0.57"/>
      <geometry>
        <box size="0.1 0.2 0.1"/>
      </geometry>
      <material name="Blue">
        <color rgba="0 0 0.8 1"/>
      </material>
    </visual>
  </link>
  <link name="r_finger_tip">
    <pose>0 0 0 0 0 </pose>
    <inertial>
      <mass value="0.1"/>
      <origin rpy="0 0 0" xyz="0 0 0"/>
      <inertia ixx="0.01" ixy="0" ixz="0" iyy="0.01" iyz="0" izz="0.01"/>
    </inertial>
    <collision name="collision_chassis">
      <origin rpy="1.5 0 0" xyz="-0.6 -0.25 0.57"/>
      <geometry>
        <box size="0.1 0.2 0.1"/>
      </geometry>
    </collision>
    <visual>
      <origin rpy="1.5 0 0" xyz="-0.6 -0.25 0.57"/>
      <geometry>
        <box size="0.1 0.2 0.1"/>
      </geometry>
      <material name="Blue">
        <color rgba="0 0 0.8 1"/>
      </material>
    </visual>
  </link>
  <!-- 
  <joint name="dummy_joint" type="fixed">
    <parent link="dummy"/>
    <child link="base_link"/>
  </joint> -->
  <joint name="junta1" type="revolute">
    <axis xyz="0 0 1"/>
    <limit effort="1000" lower="-3.13" upper="3.13" velocity="0.2"/>
    <origin rpy="0 0 0" xyz="0 0 0.45"/>
    <parent link="base_link"/>
    <child link="base"/>
    <dynamics damping="0" friction="10"/>
  </joint>
  <static>true</static>
  <joint name="junta2" type="revolute">
    <axis xyz="0 1 0"/>
    <limit effort="1000" lower="0" upper="1.6" velocity="0.2"/>
    <origin rpy="0 0 0" xyz="0 0 0.5"/>
    <parent link="base"/>
    <child link="ligacao"/>
    <dynamics damping="0" friction="10"/>
  </joint>
  <static>true</static>
  <joint name="junta3" type="revolute">
    <axis xyz="0 1 0"/>
    <limit effort="1000" lower="0" upper="1.6" velocity="0.2"/>
    <origin rpy="0 0 0" xyz="0 0 1.1"/>
    <parent link="ligacao"/>
    <child link="braco"/>
    <dynamics damping="0" friction="10"/>
  </joint>
  <static>true</static>
  <joint name="junta4" type="revolute">
    <axis xyz="0 1 0"/>
    <limit effort="1000" lower="-0.9" upper="0.9" velocity="0.2"/>
    <origin rpy="0 0 0" xyz="0 0 1.2"/>
    <parent link="braco"/>
    <child link="antepunho"/>
    <dynamics damping="0" friction="10"/>
  </joint>
  <static>true</static>
  <joint name="junta5" type="revolute">
    <axis xyz="0 0 -1"/>
    <limit effort="1000" lower="-3.14" upper="3.14" velocity="0.2"/>
    <origin rpy="0 0 0" xyz="0 0 0.12"/>
    <parent link="antepunho"/>
    <child link="punho"/>
    <dynamics damping="0" friction="10"/>
  </joint>
  <static>true</static>
  <joint name="ligarra" type="revolute">
    <axis xyz="0 0 1"/>
    <limit effort="1000" lower="-0.3" upper="0.5" velocity="0.2"/>
    <origin rpy="0 0 0" xyz="0 0 0"/>
    <parent link="punho"/>
    <child link="riser"/>
    <dynamics damping="0" friction="10"/>
  </joint>
  <static>true</static>
  <joint name="palm_riser" type="prismatic">
    <axis xyz="1 0 0"/>
    <limit effort="1000" lower="0.2" upper="1.1" velocity="0.2"/>
    <origin rpy="0 0 0" xyz="0 0 0"/>
    <parent link="riser"/>
    <child link="palm"/>
    <dynamics damping="0" friction="10"/>
  </joint>
  <static>true</static>
  <joint name="palm_right_finger" type="revolute">
    <axis xyz="-1 0 0"/>
    <limit effort="1000" lower="0" upper="0.25" velocity="0.2"/>
    <origin rpy="0 0 0" xyz="0 0 0"/>
    <parent link="palm"/>
    <child link="right_finger"/>
    <dynamics damping="0" friction="10"/>
  </joint>
  <static>true</static>
  <joint name="palm_left_finger" type="revolute">
    <axis xyz="1 0 0"/>
    <limit effort="1000" lower="0" upper="0.25" velocity="0.2"/>
    <origin rpy="0 0 0" xyz="0 0 0"/>
    <parent link="palm"/>
    <child link="left_finger"/>
    <dynamics damping="0" friction="10"/>
  </joint>
  <static>true</static>
  <joint name="left_finger_tip" type="revolute">
    <axis xyz="1 0 0"/>
    <limit effort="1000" lower="0" upper="0.04" velocity="0.2"/>
    <origin rpy="0 0 0" xyz="0 0 0"/>
    <parent link="left_finger"/>
    <child link="l_finger_tip"/>
    <dynamics damping="0" friction="10"/>
  </joint>
  <static>true</static>
  <joint name="right_finger_tip" type="revolute">
    <axis xyz="-1 0 0"/>
    <limit effort="1000" lower="0" upper="0.04" velocity="0.2"/>
    <origin rpy="0 0 0" xyz="0 0 0"/>
    <parent link="right_finger"/>
    <child link="r_finger_tip"/>
    <dynamics damping="0" friction="10"/>
  </joint>
  <static>true</static>
  <transmission name="tran_1">
    <type>transmission_interface/SimpleTransmission</type>
    <joint name="junta1">
      <hardwareInterface>hardware_interface/EffortJointInterface</hardwareInterface>
    </joint>
    <actuator name="motor__1">
      <hardwareInterface>hardware_interface/EffortJointInterface</hardwareInterface>
      <mechanicalReduction>1</mechanicalReduction>
    </actuator>
  </transmission>
  <transmission name="tran_2">
    <type>transmission_interface/SimpleTransmission</type>
    <joint name="junta2">
      <hardwareInterface>hardware_interface/EffortJointInterface</hardwareInterface>
    </joint>
    <actuator name="motor__2">
      <hardwareInterface>hardware_interface/EffortJointInterface</hardwareInterface>
      <mechanicalReduction>1</mechanicalReduction>
    </actuator>
  </transmission>
  <transmission name="tran_3">
    <type>transmission_interface/SimpleTransmission</type>
    <joint name="junta3">
      <hardwareInterface>hardware_interface/EffortJointInterface</hardwareInterface>
    </joint>
    <actuator name="motor__3">
      <hardwareInterface>hardware_interface/EffortJointInterface</hardwareInterface>
      <mechanicalReduction>1</mechanicalReduction>
    </actuator>
  </transmission>
  <transmission name="tran_4">
    <type>transmission_interface/SimpleTransmission</type>
    <joint name="junta4">
      <hardwareInterface>hardware_interface/EffortJointInterface</hardwareInterface>
    </joint>
    <actuator name="motor__4">
      <hardwareInterface>hardware_interface/EffortJointInterface</hardwareInterface>
      <mechanicalReduction>1</mechanicalReduction>
    </actuator>
  </transmission>
  <transmission name="tran_5">
    <type>transmission_interface/SimpleTransmission</type>
    <joint name="junta5">
      <hardwareInterface>hardware_interface/EffortJointInterface</hardwareInterface>
    </joint>
    <actuator name="motor__5">
      <hardwareInterface>hardware_interface/EffortJointInterface</hardwareInterface>
      <mechanicalReduction>1</mechanicalReduction>
    </actuator>
  </transmission>
  <transmission name="tran_6">
    <type>transmission_interface/SimpleTransmission</type>
    <joint name="ligarra">
      <hardwareInterface>hardware_interface/EffortJointInterface</hardwareInterface>
    </joint>
    <actuator name="motor__6">
      <hardwareInterface>hardware_interface/EffortJointInterface</hardwareInterface>
      <mechanicalReduction>1</mechanicalReduction>
    </actuator>
  </transmission>
  <transmission name="tran_7">
    <type>transmission_interface/SimpleTransmission</type>
    <joint name="palm_riser">
      <hardwareInterface>hardware_interface/EffortJointInterface</hardwareInterface>
    </joint>
    <actuator name="motor__7">
      <hardwareInterface>hardware_interface/EffortJointInterface</hardwareInterface>
      <mechanicalReduction>1</mechanicalReduction>
    </actuator>
  </transmission>
  <transmission name="tran_8">
    <type>transmission_interface/SimpleTransmission</type>
    <joint name="palm_left_finger">
      <hardwareInterface>hardware_interface/EffortJointInterface</hardwareInterface>
    </joint>
    <actuator name="motor__8">
      <hardwareInterface>hardware_interface/EffortJointInterface</hardwareInterface>
      <mechanicalReduction>1</mechanicalReduction>
    </actuator>
  </transmission>
  <transmission name="tran_9">
    <type>transmission_interface/SimpleTransmission</type>
    <joint name="left_finger_tip">
      <hardwareInterface>hardware_interface/EffortJointInterface</hardwareInterface>
    </joint>
    <actuator name="motor__9">
      <hardwareInterface>hardware_interface/EffortJointInterface</hardwareInterface>
      <mechanicalReduction>1</mechanicalReduction>
    </actuator>
  </transmission>
  <transmission name="tran_10">
    <type>transmission_interface/SimpleTransmission</type>
    <joint name="palm_right_finger">
      <hardwareInterface>hardware_interface/EffortJointInterface</hardwareInterface>
    </joint>
    <actuator name="motor__10">
      <hardwareInterface>hardware_interface/EffortJointInterface</hardwareInterface>
      <mechanicalReduction>1</mechanicalReduction>
    </actuator>
  </transmission>
  <transmission name="tran_11">
    <type>transmission_interface/SimpleTransmission</type>
    <joint name="right_finger_tip">
      <hardwareInterface>hardware_interface/EffortJointInterface</hardwareInterface>
    </joint>
    <actuator name="motor__11">
      <hardwareInterface>hardware_interface/EffortJointInterface</hardwareInterface>
      <mechanicalReduction>1</mechanicalReduction>
    </actuator>
  </transmission>
  <gazebo>
    <plugin filename="libgazebo_ros_control.so" name="gazebo_ros_control">
      <robotNamespace>/robot</robotNamespace>
    </plugin>
  </gazebo>
</robot>
